<?xml version="1.0" encoding="utf-8"?>
<!-- This URDF was automatically created by SolidWorks to URDF Exporter! Originally created by Stephen Brawner (brawner@gmail.com) 
     Commit Version: 1.6.0-1-g15f4949  Build Version: 1.6.7594.29634
     For more information, please see http://wiki.ros.org/sw_urdf_exporter -->
<robot
  name="linkerhand_l20_left.urdf">
  <link
    name="hand_base_link">
    <inertial>
      <origin
        xyz="-0.0119148743534565 0.00244694305387424 0.0878263905588916"
        rpy="0 0 0" />
      <mass
        value="0.101492069055989" />
      <inertia
        ixx="0.00029225127950738"
        ixy="1.02375483704463E-06"
        ixz="2.93624183672648E-05"
        iyy="0.000213731207869946"
        iyz="1.09167929629602E-06"
        izz="0.000114547719899272" />
    </inertial>
    <visual>
      <origin
        xyz="0 0 0"
        rpy="0 0 0" />
      <geometry>
        <mesh
          filename="meshes/hand_base_link.STL" />
      </geometry>
      <material
        name="">
        <color
          rgba="1 1 1 1" />
      </material>
    </visual>
    <collision>
      <origin
        xyz="0 0 0"
        rpy="0 0 0" />
      <geometry>
        <mesh
          filename="meshes/hand_base_link.STL" />
      </geometry>
    </collision>
  </link>
  <link
    name="thumb_metacarpals_base1">
    <inertial>
      <origin
        xyz="0.0127895410312684 -0.00250882072989859 0.00163056589077397"
        rpy="0 0 0" />
      <mass
        value="0.00274839797669793" />
      <inertia
        ixx="2.95789756987501E-07"
        ixy="1.62801523068308E-08"
        ixz="-1.23978459819709E-08"
        iyy="9.81481693443978E-08"
        iyz="1.15835532157497E-08"
        izz="2.81862454163459E-07" />
    </inertial>
    <visual>
      <origin
        xyz="0 0 0"
        rpy="0 0 0" />
      <geometry>
        <mesh
          filename="meshes/thumb_metacarpals_base1.STL" />
      </geometry>
      <material
        name="">
        <color
          rgba="0.952941176470588 0.996078431372549 0.694117647058824 1" />
      </material>
    </visual>
    <collision>
      <origin
        xyz="0 0 0"
        rpy="0 0 0" />
      <geometry>
        <mesh
          filename="meshes/thumb_metacarpals_base1.STL" />
      </geometry>
    </collision>
  </link>
  <joint
    name="thumb_cmc_roll"
    type="revolute">
    <origin
      xyz="-0.000566250268316748 -0.00508587816314111 0.0573919459698274"
      rpy="0 0 0" />
    <parent
      link="hand_base_link" />
    <child
      link="thumb_metacarpals_base1" />
    <axis
      xyz="-0.999999999999989 0 0" />
    <limit
      lower="-0.5"
      upper="0.8"
      effort="100"
      velocity="1" />
  </joint>
  <link
    name="thumb_metacarpals_base2">
    <inertial>
      <origin
        xyz="0.00091436913489587 -0.00935976528217774 -0.00155053524866945"
        rpy="0 0 0" />
      <mass
        value="0.00427940802750865" />
      <inertia
        ixx="6.79830652557537E-07"
        ixy="7.5700697333604E-08"
        ixz="-4.48172509472316E-08"
        iyy="3.39547771057385E-07"
        iyz="1.13949380135091E-07"
        izz="5.02232646466429E-07" />
    </inertial>
    <visual>
      <origin
        xyz="0 0 0"
        rpy="0 0 0" />
      <geometry>
        <mesh
          filename="meshes/thumb_metacarpals_base2.STL" />
      </geometry>
      <material
        name="">
        <color
          rgba="0.823529411764706 0.823529411764706 1 1" />
      </material>
    </visual>
    <collision>
      <origin
        xyz="0 0 0"
        rpy="0 0 0" />
      <geometry>
        <mesh
          filename="meshes/thumb_metacarpals_base2.STL" />
      </geometry>
    </collision>
  </link>
  <joint
    name="thumb_cmc_yaw"
    type="revolute">
    <origin
      xyz="0.0245077602402008 -0.000833339999216351 0"
      rpy="0 0 0" />
    <parent
      link="thumb_metacarpals_base1" />
    <child
      link="thumb_metacarpals_base2" />
    <axis
      xyz="0 0 0.999999999999989" />
    <limit
      lower="0.15"
      upper="2.2"
      effort="100"
      velocity="1" />
  </joint>
  <link
    name="thumb_metacarpals">
    <inertial>
      <origin
        xyz="0.00367448933834852 -0.00796936221759142 0.026216498568542"
        rpy="0 0 0" />
      <mass
        value="0.0120240677638171" />
      <inertia
        ixx="4.13899334404591E-06"
        ixy="1.60230655057446E-08"
        ixz="1.8332253169551E-07"
        iyy="4.84285467870166E-06"
        iyz="5.77348282958799E-08"
        izz="1.22734475239126E-06" />
    </inertial>
    <visual>
      <origin
        xyz="0 0 0"
        rpy="0 0 0" />
      <geometry>
        <mesh
          filename="meshes/thumb_metacarpals.STL" />
      </geometry>
      <material
        name="">
        <color
          rgba="0.823529411764706 0.823529411764706 1 1" />
      </material>
    </visual>
    <collision>
      <origin
        xyz="0 0 0"
        rpy="0 0 0" />
      <geometry>
        <mesh
          filename="meshes/thumb_metacarpals.STL" />
      </geometry>
    </collision>
  </link>
  <joint
    name="thumb_cmc_pitch"
    type="revolute">
    <origin
      xyz="0 -0.0307945049899851 0.00396440225285005"
      rpy="0 -0.767096499588843 1.57079617863246" />
    <parent
      link="thumb_metacarpals_base2" />
    <child
      link="thumb_metacarpals" />
    <axis
      xyz="0 1 0" />
    <limit
      lower="0"
      upper="0.6"
      effort="100"
      velocity="1" />
  </joint>
  <link
    name="thumb_proximal">
    <inertial>
      <origin
        xyz="-0.00196476724732959 -0.000244186706447158 0.0123612439174935"
        rpy="0 0 0" />
      <mass
        value="0.00531602156580031" />
      <inertia
        ixx="6.23935550125038E-07"
        ixy="-2.49370597520143E-09"
        ixz="-8.89136577147006E-08"
        iyy="6.66979410162513E-07"
        iyz="-1.18822298507521E-08"
        izz="3.98958182850857E-07" />
    </inertial>
    <visual>
      <origin
        xyz="0 0 0"
        rpy="0 0 0" />
      <geometry>
        <mesh
          filename="meshes/thumb_proximal.STL" />
      </geometry>
      <material
        name="">
        <color
          rgba="1 1 1 1" />
      </material>
    </visual>
    <collision>
      <origin
        xyz="0 0 0"
        rpy="0 0 0" />
      <geometry>
        <mesh
          filename="meshes/thumb_proximal.STL" />
      </geometry>
    </collision>
  </link>
  <joint
    name="thumb_mcp"
    type="revolute">
    <origin
      xyz="0.00467511679938065 0.00010004081575718 0.0560361883792787"
      rpy="0 0 0" />
    <parent
      link="thumb_metacarpals" />
    <child
      link="thumb_proximal" />
    <axis
      xyz="0 1 0" />
    <limit
      lower="0"
      upper="1.2"
      effort="100"
      velocity="1" />
  </joint>
  <link
    name="thumb_distal">
    <inertial>
      <origin
        xyz="-0.000156787107686532 3.97911537203255E-06 0.00939729735725905"
        rpy="0 0 0" />
      <mass
        value="0.00432493724895246" />
      <inertia
        ixx="4.13650356383133E-07"
        ixy="-4.83478229403318E-12"
        ixz="8.26300981092417E-08"
        iyy="3.90069876973653E-07"
        iyz="1.62728045295109E-10"
        izz="2.29900115532846E-07" />
    </inertial>
    <visual>
      <origin
        xyz="0 0 0"
        rpy="0 0 0" />
      <geometry>
        <mesh
          filename="meshes/thumb_distal.STL" />
      </geometry>
      <material
        name="">
        <color
          rgba="0.823529411764706 0.823529411764706 1 1" />
      </material>
    </visual>
    <collision>
      <origin
        xyz="0 0 0"
        rpy="0 0 0" />
      <geometry>
        <mesh
          filename="meshes/thumb_distal.STL" />
      </geometry>
    </collision>
  </link>
  <joint
    name="thumb_ip"
    type="revolute">
    <origin
      xyz="-0.00294430789962509 0 0.0344361391557164"
      rpy="0 0 0" />
    <parent
      link="thumb_proximal" />
    <child
      link="thumb_distal" />
    <axis
      xyz="0 1 0" />
    <limit
      lower="0"
      upper="1.2"
      effort="100"
      velocity="1" />
    <mimic
      joint="thumb_mcp"
      multiplier="1"
      offset="0" />
  </joint>
  <link
    name="index_metacarpals">
    <inertial>
      <origin
        xyz="0.0059116226670245 1.24381489410505E-06 0.002336663088224"
        rpy="0 0 0" />
      <mass
        value="0.000826416925828409" />
      <inertia
        ixx="3.46900788673765E-08"
        ixy="-4.94570060292605E-12"
        ixz="-4.21639567754915E-09"
        iyy="2.23815226099384E-08"
        iyz="-3.42869175805495E-12"
        izz="3.81307901736939E-08" />
    </inertial>
    <visual>
      <origin
        xyz="0 0 0"
        rpy="0 0 0" />
      <geometry>
        <mesh
          filename="meshes/index_metacarpals.STL" />
      </geometry>
      <material
        name="">
        <color
          rgba="1 1 1 1" />
      </material>
    </visual>
    <collision>
      <origin
        xyz="0 0 0"
        rpy="0 0 0" />
      <geometry>
        <mesh
          filename="meshes/index_metacarpals.STL" />
      </geometry>
    </collision>
  </link>
  <joint
    name="index_mcp_roll"
    type="revolute">
    <origin
      xyz="-0.0236662629253359 -0.0267021153669649 0.159311473821529"
      rpy="0 0 0" />
    <parent
      link="hand_base_link" />
    <child
      link="index_metacarpals" />
    <axis
      xyz="0.999999999999989 0 0" />
    <limit
      lower="-0.18"
      upper="0.18"
      effort="100"
      velocity="1" />
  </joint>
  <link
    name="index_proximal">
    <inertial>
      <origin
        xyz="-0.00106078131266901 2.55750531230475E-05 0.0228291737829857"
        rpy="0 0 0" />
      <mass
        value="0.00454034378439372" />
      <inertia
        ixx="8.03482369839182E-07"
        ixy="1.48649914455092E-11"
        ixz="2.21021834598009E-08"
        iyy="7.93210005255178E-07"
        iyz="-7.04429905546383E-10"
        izz="2.60969045351008E-07" />
    </inertial>
    <visual>
      <origin
        xyz="0 0 0"
        rpy="0 0 0" />
      <geometry>
        <mesh
          filename="meshes/index_proximal.STL" />
      </geometry>
      <material
        name="">
        <color
          rgba="1 1 1 1" />
      </material>
    </visual>
    <collision>
      <origin
        xyz="0 0 0"
        rpy="0 0 0" />
      <geometry>
        <mesh
          filename="meshes/index_proximal.STL" />
      </geometry>
    </collision>
  </link>
  <joint
    name="index_mcp_pitch"
    type="revolute">
    <origin
      xyz="0.01087006638288 -1.2630433198893E-05 0"
      rpy="0 0 0" />
    <parent
      link="index_metacarpals" />
    <child
      link="index_proximal" />
    <axis
      xyz="0 0.999999999999978 0" />
    <limit
      lower="0"
      upper="1.33"
      effort="100"
      velocity="1" />
  </joint>
  <link
    name="index_middle">
    <inertial>
      <origin
        xyz="-0.00201300292449436 1.2092957977234E-05 0.0157265974036625"
        rpy="0 0 0" />
      <mass
        value="0.0018096470933759" />
      <inertia
        ixx="2.06072982960832E-07"
        ixy="-2.88656520872837E-13"
        ixz="8.92137536120426E-09"
        iyy="1.73233620341224E-07"
        iyz="1.60841307210769E-12"
        izz="7.97841922375294E-08" />
    </inertial>
    <visual>
      <origin
        xyz="0 0 0"
        rpy="0 0 0" />
      <geometry>
        <mesh
          filename="meshes/index_middle.STL" />
      </geometry>
      <material
        name="">
        <color
          rgba="0.952941176470588 0.996078431372549 0.694117647058824 1" />
      </material>
    </visual>
    <collision>
      <origin
        xyz="0 0 0"
        rpy="0 0 0" />
      <geometry>
        <mesh
          filename="meshes/index_middle.STL" />
      </geometry>
    </collision>
  </link>
  <joint
    name="index_pip"
    type="revolute">
    <origin
      xyz="-0.00419480624913221 0 0.0448194128870992"
      rpy="0 0 0" />
    <parent
      link="index_proximal" />
    <child
      link="index_middle" />
    <axis
      xyz="0 0.999999999999978 0" />
    <limit
      lower="0"
      upper="1.77"
      effort="100"
      velocity="1" />
  </joint>
  <link
    name="index_distal">
    <inertial>
      <origin
        xyz="-0.00765528957648076 1.71858539162253E-05 0.00664110531798134"
        rpy="0 0 0" />
      <mass
        value="0.00386200107962104" />
      <inertia
        ixx="2.03076988239249E-07"
        ixy="-1.68898885683265E-10"
        ixz="7.21653597112048E-08"
        iyy="2.26886615426341E-07"
        iyz="4.65270572010848E-11"
        izz="1.46090205055279E-07" />
    </inertial>
    <visual>
      <origin
        xyz="0 0 0"
        rpy="0 0 0" />
      <geometry>
        <mesh
          filename="meshes/index_distal.STL" />
      </geometry>
      <material
        name="">
        <color
          rgba="0.823529411764706 0.823529411764706 1 1" />
      </material>
    </visual>
    <collision>
      <origin
        xyz="0 0 0"
        rpy="0 0 0" />
      <geometry>
        <mesh
          filename="meshes/index_distal.STL" />
      </geometry>
    </collision>
  </link>
  <joint
    name="index_dip"
    type="revolute">
    <origin
      xyz="0.00275581955818074 0 0.0317033719231916"
      rpy="0 0 0" />
    <parent
      link="index_middle" />
    <child
      link="index_distal" />
    <axis
      xyz="0 0.999999999999978 0" />
    <limit
      lower="0"
      upper="1.43"
      effort="100"
      velocity="1" />
    <mimic
      joint="index_pip"
      multiplier="0.807909"
      offset="0" />
  </joint>
  <link
    name="middle_metacarpals">
    <inertial>
      <origin
        xyz="0.00591162266983494 1.23038485751181E-06 0.00233666308822397"
        rpy="0 0 0" />
      <mass
        value="0.000826416925828398" />
      <inertia
        ixx="3.46900788448415E-08"
        ixy="-4.97366320665279E-12"
        ixz="-4.21639568532751E-09"
        iyy="2.23815226324729E-08"
        iyz="-3.41911294154389E-12"
        izz="3.81307901736936E-08" />
    </inertial>
    <visual>
      <origin
        xyz="0 0 0"
        rpy="0 0 0" />
      <geometry>
        <mesh
          filename="meshes/middle_metacarpals.STL" />
      </geometry>
      <material
        name="">
        <color
          rgba="1 1 1 1" />
      </material>
    </visual>
    <collision>
      <origin
        xyz="0 0 0"
        rpy="0 0 0" />
      <geometry>
        <mesh
          filename="meshes/middle_metacarpals.STL" />
      </geometry>
    </collision>
  </link>
  <joint
    name="middle_mcp_roll"
    type="revolute">
    <origin
      xyz="-0.028550041829013 -0.00510211872877702 0.163804366151529"
      rpy="0 0 0" />
    <parent
      link="hand_base_link" />
    <child
      link="middle_metacarpals" />
    <axis
      xyz="0.999999999997074 0 0" />
    <limit
      lower="-0.18"
      upper="0.18"
      effort="100"
      velocity="1" />
  </joint>
  <link
    name="middle_proximal">
    <inertial>
      <origin
        xyz="-0.00106078125509512 2.55774616831905E-05 0.0228291737811873"
        rpy="0 0 0" />
      <mass
        value="0.00454034378346624" />
      <inertia
        ixx="8.03482369774356E-07"
        ixy="1.48416643338212E-11"
        ixz="2.21021818913762E-08"
        iyy="7.93210005078348E-07"
        iyz="-7.04480074835338E-10"
        izz="2.60969045312818E-07" />
    </inertial>
    <visual>
      <origin
        xyz="0 0 0"
        rpy="0 0 0" />
      <geometry>
        <mesh
          filename="meshes/middle_proximal.STL" />
      </geometry>
      <material
        name="">
        <color
          rgba="1 1 1 1" />
      </material>
    </visual>
    <collision>
      <origin
        xyz="0 0 0"
        rpy="0 0 0" />
      <geometry>
        <mesh
          filename="meshes/middle_proximal.STL" />
      </geometry>
    </collision>
  </link>
  <joint
    name="middle_mcp_pitch"
    type="revolute">
    <origin
      xyz="0.0108700663541581 -1.26551278382542E-05 0"
      rpy="0 0 0" />
    <parent
      link="middle_metacarpals" />
    <child
      link="middle_proximal" />
    <axis
      xyz="0 0.999999999997063 0" />
    <limit
      lower="0"
      upper="1.33"
      effort="100"
      velocity="1" />
  </joint>
  <link
    name="middle_middle">
    <inertial>
      <origin
        xyz="-0.0020130028969762 1.20975311216631E-05 0.0157265974033742"
        rpy="0 0 0" />
      <mass
        value="0.00180964709329765" />
      <inertia
        ixx="2.06072982964894E-07"
        ixy="-3.63263662837678E-13"
        ixz="8.92137536948434E-09"
        iyy="1.73233620341022E-07"
        iyz="1.58814752956499E-12"
        izz="7.97841922399522E-08" />
    </inertial>
    <visual>
      <origin
        xyz="0 0 0"
        rpy="0 0 0" />
      <geometry>
        <mesh
          filename="meshes/middle_middle.STL" />
      </geometry>
      <material
        name="">
        <color
          rgba="0.952941176470588 0.996078431372549 0.694117647058824 1" />
      </material>
    </visual>
    <collision>
      <origin
        xyz="0 0 0"
        rpy="0 0 0" />
      <geometry>
        <mesh
          filename="meshes/middle_middle.STL" />
      </geometry>
    </collision>
  </link>
  <joint
    name="middle_pip"
    type="revolute">
    <origin
      xyz="-0.00419480624913501 0 0.0448194128870992"
      rpy="0 0 0" />
    <parent
      link="middle_proximal" />
    <child
      link="middle_middle" />
    <axis
      xyz="0 0.999999999997063 0" />
    <limit
      lower="0"
      upper="1.77"
      effort="100"
      velocity="1" />
  </joint>
  <link
    name="middle_distal">
    <inertial>
      <origin
        xyz="-0.00765529200491016 1.72040491666012E-05 0.00664110864544543"
        rpy="0 0 0" />
      <mass
        value="0.00386200248743799" />
      <inertia
        ixx="2.03076993643721E-07"
        ixy="-1.6881768758217E-10"
        ixz="7.21653773421357E-08"
        iyy="2.26886711161332E-07"
        iyz="4.63563384580481E-11"
        izz="1.46090301204891E-07" />
    </inertial>
    <visual>
      <origin
        xyz="0 0 0"
        rpy="0 0 0" />
      <geometry>
        <mesh
          filename="meshes/middle_distal.STL" />
      </geometry>
      <material
        name="">
        <color
          rgba="0.823529411764706 0.823529411764706 1 1" />
      </material>
    </visual>
    <collision>
      <origin
        xyz="0 0 0"
        rpy="0 0 0" />
      <geometry>
        <mesh
          filename="meshes/middle_distal.STL" />
      </geometry>
    </collision>
  </link>
  <joint
    name="middle_dip"
    type="revolute">
    <origin
      xyz="0.00275581955816206 0 0.0317033719231916"
      rpy="0 0 0" />
    <parent
      link="middle_middle" />
    <child
      link="middle_distal" />
    <axis
      xyz="0 0.999999999997063 0" />
    <limit
      lower="0"
      upper="1.43"
      effort="100"
      velocity="1" />
    <mimic
      joint="middle_pip"
      multiplier="0.807909"
      offset="0" />
  </joint>
  <link
    name="ring_metacarpals">
    <inertial>
      <origin
        xyz="0.00591162266983489 1.23038485749793E-06 0.00233666308822397"
        rpy="0 0 0" />
      <mass
        value="0.000826416925828383" />
      <inertia
        ixx="3.46900788448411E-08"
        ixy="-4.97366320674972E-12"
        ixz="-4.21639568532752E-09"
        iyy="2.23815226324725E-08"
        iyz="-3.41911294155036E-12"
        izz="3.81307901736931E-08" />
    </inertial>
    <visual>
      <origin
        xyz="0 0 0"
        rpy="0 0 0" />
      <geometry>
        <mesh
          filename="meshes/ring_metacarpals.STL" />
      </geometry>
      <material
        name="">
        <color
          rgba="1 1 1 1" />
      </material>
    </visual>
    <collision>
      <origin
        xyz="0 0 0"
        rpy="0 0 0" />
      <geometry>
        <mesh
          filename="meshes/ring_metacarpals.STL" />
      </geometry>
    </collision>
  </link>
  <joint
    name="ring_mcp_roll"
    type="revolute">
    <origin
      xyz="-0.026245256656013 0.016497885055223 0.159311479072529"
      rpy="0 0 0" />
    <parent
      link="hand_base_link" />
    <child
      link="ring_metacarpals" />
    <axis
      xyz="0.999999999997074 0 0" />
    <limit
      lower="-0.18"
      upper="0.18"
      effort="100"
      velocity="1" />
  </joint>
  <link
    name="ring_proximal">
    <inertial>
      <origin
        xyz="-0.00106078125525755 2.55774617305138E-05 0.0228291737812394"
        rpy="0 0 0" />
      <mass
        value="0.00454034378337052" />
      <inertia
        ixx="8.03482369771966E-07"
        ixy="1.48416625289382E-11"
        ixz="2.21021818894142E-08"
        iyy="7.93210005070933E-07"
        iyz="-7.04480073721233E-10"
        izz="2.60969045305925E-07" />
    </inertial>
    <visual>
      <origin
        xyz="0 0 0"
        rpy="0 0 0" />
      <geometry>
        <mesh
          filename="meshes/ring_proximal.STL" />
      </geometry>
      <material
        name="">
        <color
          rgba="1 1 1 1" />
      </material>
    </visual>
    <collision>
      <origin
        xyz="0 0 0"
        rpy="0 0 0" />
      <geometry>
        <mesh
          filename="meshes/ring_proximal.STL" />
      </geometry>
    </collision>
  </link>
  <joint
    name="ring_mcp_pitch"
    type="revolute">
    <origin
      xyz="0.0108700663541581 -1.26551278382542E-05 0"
      rpy="0 0 0" />
    <parent
      link="ring_metacarpals" />
    <child
      link="ring_proximal" />
    <axis
      xyz="0 0.999999999997063 0" />
    <limit
      lower="0"
      upper="1.33"
      effort="100"
      velocity="1" />
  </joint>
  <link
    name="ring_middle">
    <inertial>
      <origin
        xyz="-0.0020130028969762 1.20975311216631E-05 0.0157265974033746"
        rpy="0 0 0" />
      <mass
        value="0.00180964709329766" />
      <inertia
        ixx="2.06072982964899E-07"
        ixy="-3.63263663294924E-13"
        ixz="8.92137536948339E-09"
        iyy="1.73233620341029E-07"
        iyz="1.58814753063583E-12"
        izz="7.97841922399553E-08" />
    </inertial>
    <visual>
      <origin
        xyz="0 0 0"
        rpy="0 0 0" />
      <geometry>
        <mesh
          filename="meshes/ring_middle.STL" />
      </geometry>
      <material
        name="">
        <color
          rgba="0.952941176470588 0.996078431372549 0.694117647058824 1" />
      </material>
    </visual>
    <collision>
      <origin
        xyz="0 0 0"
        rpy="0 0 0" />
      <geometry>
        <mesh
          filename="meshes/ring_middle.STL" />
      </geometry>
    </collision>
  </link>
  <joint
    name="ring_pip"
    type="revolute">
    <origin
      xyz="-0.00419480624913501 0 0.0448194128870992"
      rpy="0 0 0" />
    <parent
      link="ring_proximal" />
    <child
      link="ring_middle" />
    <axis
      xyz="0 0.999999999997063 0" />
    <limit
      lower="0"
      upper="1.77"
      effort="100"
      velocity="1" />
  </joint>
  <link
    name="ring_distal">
    <inertial>
      <origin
        xyz="-0.00765528943882435 1.72032067655425E-05 0.00664110513859351"
        rpy="0 0 0" />
      <mass
        value="0.00386200102769892" />
      <inertia
        ixx="2.0307698528787E-07"
        ixy="-1.68846414676067E-10"
        ixz="7.21653571631685E-08"
        iyy="2.26886610649043E-07"
        iyz="4.6364052610047E-11"
        izz="1.46090200844523E-07" />
    </inertial>
    <visual>
      <origin
        xyz="0 0 0"
        rpy="0 0 0" />
      <geometry>
        <mesh
          filename="meshes/ring_distal.STL" />
      </geometry>
      <material
        name="">
        <color
          rgba="0.823529411764706 0.823529411764706 1 1" />
      </material>
    </visual>
    <collision>
      <origin
        xyz="0 0 0"
        rpy="0 0 0" />
      <geometry>
        <mesh
          filename="meshes/ring_distal.STL" />
      </geometry>
    </collision>
  </link>
  <joint
    name="ring_dip"
    type="revolute">
    <origin
      xyz="0.00275581955816206 0 0.0317033719231916"
      rpy="0 0 0" />
    <parent
      link="ring_middle" />
    <child
      link="ring_distal" />
    <axis
      xyz="0 0.999999999997063 0" />
    <limit
      lower="0"
      upper="1.43"
      effort="100"
      velocity="1" />
    <mimic
      joint="ring_pip"
      multiplier="0.807909"
      offset="0" />
  </joint>
  <link
    name="pinky_metacarpals">
    <inertial>
      <origin
        xyz="0.00591162266749565 1.24689599034777E-06 0.00233666308538993"
        rpy="0 0 0" />
      <mass
        value="0.000826416925828368" />
      <inertia
        ixx="3.46900788636364E-08"
        ixy="-4.95991695118001E-12"
        ixz="-4.21639566757935E-09"
        iyy="2.2381522598176E-08"
        iyz="-3.3913239149834E-12"
        izz="3.81307901891933E-08" />
    </inertial>
    <visual>
      <origin
        xyz="0 0 0"
        rpy="0 0 0" />
      <geometry>
        <mesh
          filename="meshes/pinky_metacarpals.STL" />
      </geometry>
      <material
        name="">
        <color
          rgba="1 1 1 1" />
      </material>
    </visual>
    <collision>
      <origin
        xyz="0 0 0"
        rpy="0 0 0" />
      <geometry>
        <mesh
          filename="meshes/pinky_metacarpals.STL" />
      </geometry>
    </collision>
  </link>
  <joint
    name="pinky_mcp_roll"
    type="revolute">
    <origin
      xyz="-0.0226215026189916 0.0380979799565023 0.150312739475098"
      rpy="0 0 0" />
    <parent
      link="hand_base_link" />
    <child
      link="pinky_metacarpals" />
    <axis
      xyz="0.999999999999863 0 0" />
    <limit
      lower="-0.18"
      upper="0.18"
      effort="100"
      velocity="1" />
  </joint>
  <link
    name="pinky_proximal">
    <inertial>
      <origin
        xyz="-0.00106078130345072 2.56273151262865E-05 0.0228291737240488"
        rpy="0 0 0" />
      <mass
        value="0.00454034378334877" />
      <inertia
        ixx="8.03482369684614E-07"
        ixy="1.49113177657717E-11"
        ixz="2.21021831948491E-08"
        iyy="7.93210001911528E-07"
        iyz="-7.05647348579671E-10"
        izz="2.6096904852503E-07" />
    </inertial>
    <visual>
      <origin
        xyz="0 0 0"
        rpy="0 0 0" />
      <geometry>
        <mesh
          filename="meshes/pinky_proximal.STL" />
      </geometry>
      <material
        name="">
        <color
          rgba="1 1 1 1" />
      </material>
    </visual>
    <collision>
      <origin
        xyz="0 0 0"
        rpy="0 0 0" />
      <geometry>
        <mesh
          filename="meshes/pinky_proximal.STL" />
      </geometry>
    </collision>
  </link>
  <joint
    name="pinky_mcp_pitch"
    type="revolute">
    <origin
      xyz="0.0108700663781205 -1.26345288001539E-05 0"
      rpy="0 0 0" />
    <parent
      link="pinky_metacarpals" />
    <child
      link="pinky_proximal" />
    <axis
      xyz="0 0.999999999997607 0" />
    <limit
      lower="0"
      upper="1.33"
      effort="100"
      velocity="1" />
  </joint>
  <link
    name="pinky_middle">
    <inertial>
      <origin
        xyz="-0.00201300292033277 1.21294435264513E-05 0.0157265973767615"
        rpy="0 0 0" />
      <mass
        value="0.00180964709325975" />
      <inertia
        ixx="2.06072982944143E-07"
        ixy="-2.807472279961E-13"
        ixz="8.92137535609903E-09"
        iyy="1.73233620335545E-07"
        iyz="1.39275282570275E-12"
        izz="7.97841922238384E-08" />
    </inertial>
    <visual>
      <origin
        xyz="0 0 0"
        rpy="0 0 0" />
      <geometry>
        <mesh
          filename="meshes/pinky_middle.STL" />
      </geometry>
      <material
        name="">
        <color
          rgba="0.952941176470588 0.996078431372549 0.694117647058824 1" />
      </material>
    </visual>
    <collision>
      <origin
        xyz="0 0 0"
        rpy="0 0 0" />
      <geometry>
        <mesh
          filename="meshes/pinky_middle.STL" />
      </geometry>
    </collision>
  </link>
  <joint
    name="pinky_pip"
    type="revolute">
    <origin
      xyz="-0.00419480624907856 0 0.0448194128869988"
      rpy="0 0 0" />
    <parent
      link="pinky_proximal" />
    <child
      link="pinky_middle" />
    <axis
      xyz="0 0.999999999997607 0" />
    <limit
      lower="0"
      upper="1.77"
      effort="100"
      velocity="1" />
  </joint>
  <link
    name="pinky_distal">
    <inertial>
      <origin
        xyz="-0.00765529202698167 1.72046074725651E-05 0.00664110856023714"
        rpy="0 0 0" />
      <mass
        value="0.00386200247559812" />
      <inertia
        ixx="2.03076993365142E-07"
        ixy="-1.68699687819137E-10"
        ixz="7.21653770979734E-08"
        iyy="2.26886710167335E-07"
        iyz="4.63101041885608E-11"
        izz="1.4609030074237E-07" />
    </inertial>
    <visual>
      <origin
        xyz="0 0 0"
        rpy="0 0 0" />
      <geometry>
        <mesh
          filename="meshes/pinky_distal.STL" />
      </geometry>
      <material
        name="">
        <color
          rgba="0.823529411764706 0.823529411764706 1 1" />
      </material>
    </visual>
    <collision>
      <origin
        xyz="0 0 0"
        rpy="0 0 0" />
      <geometry>
        <mesh
          filename="meshes/pinky_distal.STL" />
      </geometry>
    </collision>
  </link>
  <joint
    name="pinky_dip"
    type="revolute">
    <origin
      xyz="0.00275581955821799 0 0.0317033719231203"
      rpy="0 0 0" />
    <parent
      link="pinky_middle" />
    <child
      link="pinky_distal" />
    <axis
      xyz="0 0.999999999997607 0" />
    <limit
      lower="0"
      upper="1.43"
      effort="100"
      velocity="1" />
    <mimic
      joint="pinky_pip"
      multiplier="0.807909"
      offset="0" />
  </joint>
</robot>